<mujoco model="ant">
  <compiler angle="degree" coordinate="local" inertiafromgeom="true"/>
  <option integrator="RK4" timestep="0.01"/>
  <custom>
    <numeric data="0.0 0.0 0.55 1.0 0.0 0.0 0.0 0.0 1.0 0.0 -1.0 0.0 -1.0 0.0 1.0" name="init_qpos"/>
  </custom>
  <default>
    <joint armature="1" damping="1" limited="true"/>
    <geom conaffinity="0" condim="3" density="5.0" friction="1 0.5 0.5" margin="0.01" rgba="0.8 0.6 0.4 1"/>
  </default>
  <asset>
    <texture builtin="gradient" height="100" rgb1="1 1 1" rgb2="0 0 0" type="skybox" width="100"/>
    <texture builtin="flat" height="1278" mark="cross" markrgb="1 1 1" name="texgeom" random="0.01" rgb1="0.8 0.6 0.4" rgb2="0.8 0.6 0.4" type="cube" width="127"/>
    <texture builtin="checker" height="100" name="texplane" rgb1="0 0 0" rgb2="0.8 0.8 0.8" type="2d" width="100"/>
    <material name="MatPlane" reflectance="0" shininess="0" specular="0" texrepeat="60 60"/>
    <material name="geom" texture="texgeom" texuniform="true"/>
  </asset>
  <worldbody>
    <light cutoff="100" diffuse="1 1 1" dir="-0 0 -1.3" directional="true" exponent="1" pos="0 0 1.3" specular=".1 .1 .1"/>
    <geom conaffinity="3" condim="3" material="MatPlane" name="floor" pos="0 0 0" rgba="0.3 0.3 0.3 1" size="100 100 100" type="plane"/>
    <body name="wall_1" pos="-50 0 0">
      <geom pos="0 0 0" size="1 50 1" type="box" rgba="0 0 0 1" contype="1" conaffinity="1"/>
    </body>
    <body name="wall_2" pos="50 0 0">
      <geom pos="0 0 0" size="1 50 1" type="box" rgba="0 0 0 1" contype="1" conaffinity="1"/>
    </body>
    <body name="wall_3" pos="0 -50 0">
      <geom pos="0 0 0" size="50 1 1" type="box" rgba="0 0 0 1" contype="1" conaffinity="1"/>
    </body>
    <body name="wall_4" pos="0 50 0">
      <geom pos="0 0 0" size="50 1 1" type="box" rgba="0 0 0 1" contype="1" conaffinity="1"/>
    </body>
    <body name="wall_5" pos="-25 0 0">
      <geom pos="0 0 0" size="1 25 1" type="box" rgba="0 0 0 1" contype="1" conaffinity="1"/>
    </body>
    <body name="wall_6" pos="0 25 0">
      <geom pos="0 0 0" size="25 1 1" type="box" rgba="0 0 0 1" contype="1" conaffinity="1"/>
    </body>
    <body name="wall_7" pos="25 0 0">
      <geom pos="0 0 0" size="1 25 1" type="box" rgba="0 0 0 1" contype="1" conaffinity="1"/>
    </body>
    <body name="wall_8" pos="12.5 -25 0">
      <geom pos="0 0 0" size="12.5 1 1" type="box" rgba="0 0 0 1" contype="1" conaffinity="1"/>
    </body>
    <body name="wall_9" pos="0 -12.5 0">
      <geom pos="0 0 0" size="1 12.5 1" type="box" rgba="0 0 0 01" contype="1" conaffinity="1"/>
    </body>
    <body name="torso" pos="45 45 0.75">
      <camera name="track" mode="fixed" pos="0 -3 0.3" xyaxes="-1 0 1 0 0 -1"/>
      <geom name="torso_geom" pos="0 0 0" size="0.25" type="sphere" rgba="1 1 1 1"/>
      <site name="torso_site" size="0.01 0.01 0.01"/>
      <joint armature="0" damping="0" limited="false" margin="0.01" name="root" pos="0 0 0" type="free"/>
      <body name="front_left_leg" pos="0 0 0">
        <geom fromto="0.0 0.0 0.0 0.2 0.2 0.0" name="aux_1_geom" size="0.08" type="capsule" rgba="1 0 0 1"/>
        <body name="aux_1" pos="0.2 0.2 0">
          <joint axis="0 0 1" name="hip_1" pos="0.0 0.0 0.0" range="-30 30" type="hinge"/>
          <geom fromto="0.0 0.0 0.0 0.2 0.2 0.0" name="left_leg_geom" size="0.08" type="capsule" rgba="1 0 0 1"/>
          <body pos="0.2 0.2 0">
            <joint axis="-1 1 0" name="ankle_1" pos="0.0 0.0 0.0" range="30 70" type="hinge"/>
            <geom fromto="0.0 0.0 0.0 0.4 0.4 0.0" name="left_ankle_geom" size="0.08" type="capsule" rgba="1 0 0 1"/>
            <site name="foot_1" size="0.09" pos=".4 .4 0" type="sphere"/>
          </body>
        </body>
      </body>
      <body name="front_right_leg" pos="0 0 0">
        <geom fromto="0.0 0.0 0.0 -0.2 0.2 0.0" name="aux_2_geom" size="0.08" type="capsule" rgba="0 1 0 1"/>
        <body name="aux_2" pos="-0.2 0.2 0">
          <joint axis="0 0 1" name="hip_2" pos="0.0 0.0 0.0" range="-30 30" type="hinge"/>
          <geom fromto="0.0 0.0 0.0 -0.2 0.2 0.0" name="right_leg_geom" size="0.08" type="capsule" rgba="0 1 0 1"/>
          <body pos="-0.2 0.2 0">
            <joint axis="1 1 0" name="ankle_2" pos="0.0 0.0 0.0" range="-70 -30" type="hinge"/>
            <geom fromto="0.0 0.0 0.0 -0.4 0.4 0.0" name="right_ankle_geom" size="0.08" type="capsule" rgba="0 1 0 1"/>
            <site name="foot_2" size="0.09" pos="-.4 .4 0" type="sphere"/>
          </body>
        </body>
      </body>
      <body name="back_leg" pos="0 0 0">
        <geom fromto="0.0 0.0 0.0 -0.2 -0.2 0.0" name="aux_3_geom" size="0.08" type="capsule" rgba="0 0 1 1"/>
        <body name="aux_3" pos="-0.2 -0.2 0">
          <joint axis="0 0 1" name="hip_3" pos="0.0 0.0 0.0" range="-30 30" type="hinge"/>
          <geom fromto="0.0 0.0 0.0 -0.2 -0.2 0.0" name="back_leg_geom" size="0.08" type="capsule" rgba="0 0 1 1"/>
          <body pos="-0.2 -0.2 0">
            <joint axis="-1 1 0" name="ankle_3" pos="0.0 0.0 0.0" range="-70 -30" type="hinge"/>
            <geom fromto="0.0 0.0 0.0 -0.4 -0.4 0.0" name="third_ankle_geom" size="0.08" type="capsule" rgba="0 0 1 1"/>
            <site name="foot_3" size="0.09" pos="-.4 -.4 0" type="sphere"/>
          </body>
        </body>
      </body>
      <body name="right_back_leg" pos="0 0 0">
        <geom fromto="0.0 0.0 0.0 0.2 -0.2 0.0" name="aux_4_geom" size="0.08" type="capsule"  rgba="1 1 0 1"/>
        <body name="aux_4" pos="0.2 -0.2 0">
          <joint axis="0 0 1" name="hip_4" pos="0.0 0.0 0.0" range="-30 30" type="hinge"/>
          <geom fromto="0.0 0.0 0.0 0.2 -0.2 0.0" name="rightback_leg_geom" size="0.08" type="capsule" rgba="1 1 0 1"/>
          <body pos="0.2 -0.2 0">
            <joint axis="1 1 0" name="ankle_4" pos="0.0 0.0 0.0" range="30 70" type="hinge"/>
            <geom fromto="0.0 0.0 0.0 0.4 -0.4 0.0" name="fourth_ankle_geom" size="0.08" type="capsule" rgba="1 1 0 1"/>
            <site name="foot_4" size="0.09" pos=".4 -.4 0" type="sphere"/>
          </body>
        </body>
      </body>
    </body>
    <body name="waypoint" pos="20 20 2">
      <geom pos="0 0 0" size="1 1 1" type="ellipsoid" rgba="1 0 0 .5" contype="2" conaffinity="0"/>
      <joint armature="0" damping="0" limited="false" margin="0.01" name="way_root" pos="0 0 0" type="free"/>
    </body>
  </worldbody>
  <actuator>
    <motor ctrllimited="true" ctrlrange="-1.0 1.0" joint="hip_1" gear="5"/>
    <motor ctrllimited="true" ctrlrange="-1.0 1.0" joint="ankle_1" gear="5"/>
    <motor ctrllimited="true" ctrlrange="-1.0 1.0" joint="hip_2" gear="5"/>
    <motor ctrllimited="true" ctrlrange="-1.0 1.0" joint="ankle_2" gear="5"/>
    <motor ctrllimited="true" ctrlrange="-1.0 1.0" joint="hip_3" gear="5"/>
    <motor ctrllimited="true" ctrlrange="-1.0 1.0" joint="ankle_3" gear="5"/>
    <motor ctrllimited="true" ctrlrange="-1.0 1.0" joint="hip_4" gear="5"/>
    <motor ctrllimited="true" ctrlrange="-1.0 1.0" joint="ankle_4" gear="5"/>
  </actuator>
  <sensor>
    <framexaxis name="x_axis" objtype="body" objname="torso" cutoff="0" noise="0"/>
    <frameyaxis name="y_axis" objtype="body" objname="torso" cutoff="0" noise="0"/>
    <framezaxis name="z_axis" objtype="body" objname="torso" cutoff="0" noise="0"/>
    <accelerometer name="accelerometer" site="torso_site" cutoff="0" noise="0"/>
    <gyro name="gyro" site="torso_site" cutoff="0" noise="0"/>
    <velocimeter name="velocimeter" site="torso_site"/>
    <jointpos name="hip_1_pos" noise="0" cutoff="0" joint="hip_1"/>
    <jointpos name="ankle_1_pos" noise="0" cutoff="0" joint="ankle_1"/>
    <jointpos name="hip_2_pos" noise="0" cutoff="0" joint="hip_2"/>
    <jointpos name="ankle_2_pos" noise="0" cutoff="0" joint="ankle_2"/>
    <jointpos name="hip_3_pos" noise="0" cutoff="0" joint="hip_3"/>
    <jointpos name="ankle_3_pos" noise="0" cutoff="0" joint="ankle_3"/>
    <jointpos name="hip_4_pos" noise="0" cutoff="0" joint="hip_4"/>
    <jointpos name="ankle_4_pos" noise="0" cutoff="0" joint="ankle_4"/>
    <jointvel name="hip_1_vel" noise="0" cutoff="0" joint="hip_1"/>
    <jointvel name="ankle_1_vel" noise="0" cutoff="0" joint="ankle_1"/>
    <jointvel name="hip_2_vel" noise="0" cutoff="0" joint="hip_2"/>
    <jointvel name="ankle_2_vel" noise="0" cutoff="0" joint="ankle_2"/>
    <jointvel name="hip_3_vel" noise="0" cutoff="0" joint="hip_3"/>
    <jointvel name="ankle_3_vel" noise="0" cutoff="0" joint="ankle_3"/>
    <jointvel name="hip_4_vel" noise="0" cutoff="0" joint="hip_4"/>
    <jointvel name="ankle_4_vel" noise="0" cutoff="0" joint="ankle_4"/>
    <touch name="foot_1_touch" site="foot_1" noise="0" cutoff="0"/>
    <touch name="foot_2_touch" site="foot_2" noise="0" cutoff="0"/>
    <touch name="foot_3_touch" site="foot_3" noise="0" cutoff="0"/>
    <touch name="foot_4_touch" site="foot_4" noise="0" cutoff="0"/>
    <framepos name="pos" noise="0" cutoff="0" objtype="body" objname="torso"/>
  </sensor>
</mujoco>
